<?xml version='1.0'?>
<sdf version='1.7'>
  <model name="joint_position_controller_demo">
      <pose>0 0 0 0 1.57 0</pose>
      <link name="base_link">
        <pose>0.0 0.0 0.0 0 0 0</pose>
        <inertial>
          <inertia>
            <ixx>2.501</ixx>
            <ixy>0</ixy>
            <ixz>0</ixz>
            <iyy>2.501</iyy>
            <iyz>0</iyz>
            <izz>5</izz>
          </inertia>
          <mass>120.0</mass>
        </inertial>
        <visual name="base_visual">
          <pose>0.0 0.0 0.0 0 0 0</pose>
          <geometry>
            <cylinder>
            	<radius>0.25</radius>
            	<length>3</length>
            </cylinder>
          </geometry>
          <material>
            <ambient>0.5 1.0 0.5 1</ambient>
            <diffuse>0.5 1.0 0.5 1</diffuse>
            <specular>0.0 1.0 0.0 1</specular>
          </material>
        </visual>
        <collision name="base_collision">
          <pose>0.0 0.0 0.0 0 0 0</pose>
          <geometry>
            <box>
              <size>0.5 0.5 0.01</size>
            </box>
          </geometry>
        </collision>
      </link>
      <link name="rotor">
        <pose>0.0 0.0 1.9 0 0 0</pose>
        <inertial>
          <inertia>
            <ixx>0.032</ixx>
            <ixy>0</ixy>
            <ixz>0</ixz>
            <iyy>0.032</iyy>
            <iyz>0</iyz>
            <izz>0.00012</izz>
          </inertia>
          <mass>0.6</mass>
        </inertial>
        <visual name="visual">
          <geometry>
            <box>
              <size>0.25 0.25 1.00</size>
            </box>
          </geometry>
          <material>
            <ambient>0.0 1.0 0.0 1</ambient>
            <diffuse>0.0 1.0 0.0 1</diffuse>
            <specular>0.0 1.0 0.0 1</specular>
          </material>
          <material>
            <ambient>0.2 0.8 0.2 1</ambient>
          </material>
        </visual>
        <collision name="collision">
          <geometry>
            <box>
              <size>0.25 0.1 0.05</size>
            </box>
          </geometry>
        </collision>
      </link>
      
      <link name="rotor2">
        <pose>0.0 0.12 2.45 -0.5 0 0</pose>
        <inertial>
          <inertia>
            <ixx>0.032</ixx>
            <ixy>0</ixy>
            <ixz>0</ixz>
            <iyy>0.032</iyy>
            <iyz>0</iyz>
            <izz>0.00012</izz>
          </inertia>
          <mass>0.02</mass>
        </inertial>
        <visual name="visual2">
          <geometry>
            <box>
              <size>0.02 0.10 0.20</size>
            </box>
          </geometry>
          <material>
            <ambient>1.0 1.0 0.0 1</ambient>
            <diffuse>1.0 1.0 0.0 1</diffuse>
            <specular>1.0 1.0 0.0 1</specular>
          </material>
          <material>
            <ambient>0.2 0.8 0.2 1</ambient>
          </material>
        </visual>
        <collision name="collision2">
          <geometry>
            <box>
              <size>0.02 0.10 0.20</size>
            </box>
          </geometry>
        </collision>
      </link>
      
      <link name="cut2">
        <pose>0.0 0.12 2.585 0.5 0 0</pose>
        <inertial>
          <inertia>
            <ixx>0.032</ixx>
            <ixy>0</ixy>
            <ixz>0</ixz>
            <iyy>0.032</iyy>
            <iyz>0</iyz>
            <izz>0.00012</izz>
          </inertia>
          <mass>0.02</mass>
        </inertial>
        <visual name="visual2">
          <geometry>
            <box>
              <size>0.02 0.08 0.20</size>
            </box>
          </geometry>
          <material>
            <ambient>1.0 1.0 0.0 1</ambient>
            <diffuse>1.0 1.0 0.0 1</diffuse>
            <specular>1.0 1.0 0.0 1</specular>
          </material>
          <material>
            <ambient>0.2 0.8 0.2 1</ambient>
          </material>
        </visual>
        <collision name="collision2">
          <geometry>
            <box>
              <size>0.02 0.08 0.20</size>
            </box>
          </geometry>
        </collision>
      </link>
      
      <link name="rotor3">
        <pose>0.0 -0.12 2.45 0.5 0 0</pose>
        <inertial>
          <inertia>
            <ixx>0.032</ixx>
            <ixy>0</ixy>
            <ixz>0</ixz>
            <iyy>0.032</iyy>
            <iyz>0</iyz>
            <izz>0.00012</izz>
          </inertia>
          <mass>0.02</mass>
        </inertial>
        <visual name="visual2">
          <geometry>
            <box>
              <size>0.02 0.10 0.20</size>
            </box>
          </geometry>
          <material>
            <ambient>1.0 1.0 0.0 1</ambient>
            <diffuse>1.0 1.0 0.0 1</diffuse>
            <specular>1.0 1.0 0.0 1</specular>
          </material>
          <material>
            <ambient>0.2 0.8 0.2 1</ambient>
          </material>
        </visual>
        <collision name="collision2">
          <geometry>
            <box>
              <size>0.02 0.10 0.20</size>
            </box>
          </geometry>
        </collision>
      </link>
      
      <link name="cut3">
        <pose>0.0 -0.12 2.585 -0.5 0 0</pose>
        <inertial>
          <inertia>
            <ixx>0.032</ixx>
            <ixy>0</ixy>
            <ixz>0</ixz>
            <iyy>0.032</iyy>
            <iyz>0</iyz>
            <izz>0.00012</izz>
          </inertia>
          <mass>0.02</mass>
        </inertial>
        <visual name="visual2">
          <geometry>
            <box>
              <size>0.02 0.08 0.20</size>
            </box>
          </geometry>
          <material>
            <ambient>1.0 1.0 0.0 1</ambient>
            <diffuse>1.0 1.0 0.0 1</diffuse>
            <specular>1.0 1.0 0.0 1</specular>
          </material>
          <material>
            <ambient>0.2 0.8 0.2 1</ambient>
          </material>
        </visual>
        <collision name="collision2">
          <geometry>
            <box>
              <size>0.02 0.08 0.20</size>
            </box>
          </geometry>
        </collision>
      </link>

      <joint name="world_fixed" type="fixed">
        <parent>world</parent>
        <child>base_link</child>
      </joint>

      <joint name="j1" type="revolute">
        <pose>0 0 -0.5 0 0 0</pose>
        <parent>base_link</parent>
        <child>rotor</child>
        <axis>
          <xyz>0 0 1</xyz>
          <dynamics>
            <damping>0.5</damping>
          </dynamics>
        </axis>
      </joint>
      
      <joint name="j2" type="revolute">
        <pose>0 0 0 0 0 0</pose>
        <parent>rotor</parent>
        <child>rotor2</child>
        <axis>
          <xyz>1 0 0</xyz>
          <dynamics>
            <damping>0.5</damping>
          </dynamics>
        </axis>
      </joint>
      
      <joint name="j5" type="revolute">
        <pose>0 0 0 0 0 0</pose>
        <parent>rotor</parent>
        <child>rotor3</child>
        <axis>
          <xyz>1 0 0</xyz>
          <dynamics>
            <damping>0.5</damping>
          </dynamics>
        </axis>
      </joint>
      
      <joint name="j3" type="fixed">
        <pose>0 0 0 0 0 0</pose>
        <parent>rotor2</parent>
        <child>cut2</child>
      </joint>
      
      <joint name="j4" type="fixed">
        <pose>0 0 0 0 0 0</pose>
        <parent>rotor3</parent>
        <child>cut3</child>
      </joint>
      
      
      <plugin
        filename="ignition-gazebo-joint-position-controller-system"
        name="gz::sim::systems::JointPositionController">
        <joint_name>j1</joint_name>
        <topic>rotor_cmd</topic>
        <p_gain>1</p_gain>
        <i_gain>0.1</i_gain>
        <d_gain>0.01</d_gain>
        <i_max>1</i_max>
        <i_min>-1</i_min>
        <cmd_max>1000</cmd_max>
        <cmd_min>-1000</cmd_min>
      </plugin>
      
      <plugin
        filename="ignition-gazebo-joint-position-controller-system"
        name="gz::sim::systems::JointPositionController">
        <joint_name>j2</joint_name>
        <topic>rotor_cmd2</topic>
        <p_gain>1</p_gain>
        <i_gain>0.1</i_gain>
        <d_gain>0.01</d_gain>
        <i_max>1</i_max>
        <i_min>-1</i_min>
        <cmd_max>100</cmd_max>
        <cmd_min>-100</cmd_min>
      </plugin>
      
      <plugin
        filename="ignition-gazebo-joint-position-controller-system"
        name="gz::sim::systems::JointPositionController">
        <joint_name>j5</joint_name>
        <topic>rotor_cmd3</topic>
        <p_gain>1</p_gain>
        <i_gain>0.1</i_gain>
        <d_gain>0.01</d_gain>
        <i_max>1</i_max>
        <i_min>-1</i_min>
        <cmd_max>100</cmd_max>
        <cmd_min>-100</cmd_min>
      </plugin> 
      
    </model>
</sdf>
